<mujoco model="arm3d">

    <compiler inertiafromgeom="true" angle="radian" coordinate="local" />
    <option timestep="0.01" gravity="0 0 0" iterations="20" integrator="RK4" />
    <default>
        <joint armature="0.04" damping="1" limited="true" />
        <geom friction=".5 .1 .1" margin="0.002" condim="1" contype="0" conaffinity="0" />
    </default>

    <worldbody>
        <body name="r_shoulder_pan_link" pos="0 -0.188 0">
            <geom name="e1" type="sphere" rgba="0.6 0.6 0.6 1" pos="-0.06 0.05 0.2" size="0.05" />
            <geom name="e2" type="sphere" rgba="0.6 0.6 0.6 1" pos=" 0.06 0.05 0.2" size="0.05" />
            <geom name="e1p" type="sphere" rgba="0.1 0.1 0.1 1" pos="-0.06 0.09 0.2" size="0.03" />
            <geom name="e2p" type="sphere" rgba="0.1 0.1 0.1 1" pos=" 0.06 0.09 0.2" size="0.03" />
            <geom name="sp" type="capsule" fromto="0 0 -0.4 0 0 0.2" size="0.1" />
            <joint name="r_shoulder_pan_joint" type="hinge" pos="0 0 0" axis="0 0 1" range="-2.2854 1.714602" damping="10.0" />

            <body name="r_shoulder_lift_link" pos="0.1 0 0">
                <geom name="sl" type="capsule" fromto="0 -0.1 0 0 0.1 0" size="0.1" />
                <joint name="r_shoulder_lift_joint" type="hinge" pos="0 0 0" axis="0 1 0" range="-0.5236 1.3963" damping="10.0" />

                <body name="r_upper_arm_roll_link" pos="0 0 0">
                    <geom name="uar" type="capsule" fromto="-0.1 0 0 0.1 0 0" size="0.02" />
                    <joint name="r_upper_arm_roll_joint" type="hinge" pos="0 0 0" axis="1 0 0" range="-3.9 0.8" damping="0.1" />

                    <body name="r_upper_arm_link" pos="0 0 0">
                        <geom name="ua" type="capsule" fromto="0 0 0 0.4 0 0" size="0.06" />

                        <body name="r_elbow_flex_link" pos="0.4 0 0">
                            <geom name="ef" type="capsule" fromto="0 -0.02 0 0.0 0.02 0" size="0.06" />
                            <joint name="r_elbow_flex_joint" type="hinge" pos="0 0 0" axis="0 1 0" range="-2.3213 0" damping="1.0" />

                            <body name="r_forearm_roll_link" pos="0 0 0">
                                <geom name="fr" type="capsule" fromto="-0.1 0 0 0.1 0 0" size="0.02" />
                                <joint name="r_forearm_roll_joint" type="hinge" limited="false" pos="0 0 0" axis="1 0 0" damping=".1" />

                                <body name="r_forearm_link" pos="0 0 0">
                                    <geom name="fa" type="capsule" fromto="0 0 0 0.321 0 0" size="0.05" />

                                    <body name="r_wrist_flex_link" pos="0.321 0 0">
                                        <geom name="wf" type="capsule" fromto="0 -0.02 0 0 0.02 0" size="0.01" />
                                        <joint name="r_wrist_flex_joint" type="hinge" pos="0 0 0" axis="0 1 0" range="-2.094 0" damping=".1" />

                                        <body name="r_wrist_roll_link" pos="0 0 0">
                                            <geom name="wr" type="capsule" fromto="-0.02 0 0 0.02 0 0" size="0.01" />
                                            <joint name="r_wrist_roll_joint" type="hinge" pos="0 0 0" limited="false" axis="1 0 0" damping="0.1" />

                                            <body name="r_gripper_palm_link" pos="0 0 0">
                                                <geom name="pl" type="capsule" fromto="0.05 0 -0.02 0.05 0 0.02" size="0.05" />

                                                <body name="r_gripper_tool_frame" pos="0.18 0 0">
                                                    <site name="leg_bottom" pos="0 0 -0.15" size="0.01" />
                                                    <site name="leg_top" pos="0 0 0.15" size="0.01" />

                                                    <body name="ball" pos="0 0 0">
                                                        <geom name="ball_geom" rgba="0.8 0.6 0.6 1" type="cylinder" fromto="0 0 -0.15 0 0 0.15" size="0.028" density="2000" contype="2" conaffinity="1" />
                                                    </body>
                                                </body>

                                                <body name="r_gripper_l_finger_link" pos="0.07691 0.03 0">
                                                    <geom name="gf3" type="capsule" fromto="0 0 0 0.09137 0.00495 0" size="0.01" />

                                                    <body name="r_gripper_l_finger_tip_link" pos="0.09137 0.00495 0">
                                                        <geom name="gf4" type="capsule" fromto="0 0 0 0.09137 0.0 0" size="0.01" />
                                                    </body>
                                                </body>

                                                <body name="r_gripper_r_finger_link" pos="0.07691 -0.03 0">
                                                    <geom name="gf1" type="capsule" fromto="0 0 0 0.09137 -0.00495 0" size="0.01" />

                                                    <body name="r_gripper_r_finger_tip_link" pos="0.09137 -0.00495 0">
                                                        <geom name="gf2" type="capsule" fromto="0 0 0 0.09137 0.0 0" size="0.01" />
                                                    </body>
                                                </body>
                                            </body>
                                        </body>
                                    </body>
                                </body>
                            </body>
                        </body>
                    </body>
                </body>
            </body>
        </body>

        <body name="toplefthole" pos="-0.1 0.1 0">
          <body name="tlg1" pos="0.034 0.3 -0.47" axisangle="0 1 0 0.05">
              <geom name="tlg1" rgba="0.2 0.2 0.2 1" type="box" size="0.003 0.01 0.05" contype="1" conaffinity="1" />
          </body>

          <body name="tlg2" pos="-0.034 0.3 -0.47" axisangle="0 1 0 -0.05">
              <geom name="tlg2" rgba="0.2 0.2 0.2 1" type="box" size="0.003 0.01 0.05" contype="1" conaffinity="1" />
          </body>

          <body name="tlg3" pos="0.0 0.334 -0.47" axisangle="1 0 0 -0.05">
              <geom name="tlg3" rgba="0.2 0.2 0.2 1" type="box" size="0.01 0.003 0.05" contype="1" conaffinity="1" />
          </body>

          <body name="tlg4" pos="0.0 0.266 -0.47" axisangle="1 0 0 0.05">
              <geom name="tlg4" rgba="0.2 0.2 0.2 1" type="box" size="0.01 0.003 0.05" contype="1" conaffinity="1" />
          </body>
        </body>

        <body name="downlefthole" pos="-0.1 -0.1 0">
          <body name="dlg1" pos="0.034 0.3 -0.47" axisangle="0 1 0 0.05">
              <geom name="dlg1" rgba="0.2 0.2 0.2 1" type="box" size="0.003 0.01 0.05" contype="1" conaffinity="1" />
          </body>

          <body name="dlg2" pos="-0.034 0.3 -0.47" axisangle="0 1 0 -0.05">
              <geom name="dlg2" rgba="0.2 0.2 0.2 1" type="box" size="0.003 0.01 0.05" contype="1" conaffinity="1" />
          </body>

          <body name="dlg3" pos="0.0 0.334 -0.47" axisangle="1 0 0 -0.05">
              <geom name="dlg3" rgba="0.2 0.2 0.2 1" type="box" size="0.01 0.003 0.05" contype="1" conaffinity="1" />
          </body>

          <body name="dlg4" pos="0.0 0.266 -0.47" axisangle="1 0 0 0.05">
              <geom name="dlg4" rgba="0.2 0.2 0.2 1" type="box" size="0.01 0.003 0.05" contype="1" conaffinity="1" />
          </body>
        </body>

        <body name="toprighthole" pos="0.1 0.1 0">
          <body name="trg1" pos="0.034 0.3 -0.47" axisangle="0 1 0 0.05">
              <geom name="trg1" rgba="0.2 0.2 0.2 1" type="box" size="0.003 0.01 0.05" contype="1" conaffinity="1" />
          </body>

          <body name="trg2" pos="-0.034 0.3 -0.47" axisangle="0 1 0 -0.05">
              <geom name="trg2" rgba="0.2 0.2 0.2 1" type="box" size="0.003 0.01 0.05" contype="1" conaffinity="1" />
          </body>

          <body name="trg3" pos="0.0 0.334 -0.47" axisangle="1 0 0 -0.05">
              <geom name="trg3" rgba="0.2 0.2 0.2 1" type="box" size="0.01 0.003 0.05" contype="1" conaffinity="1" />
          </body>

          <body name="trg4" pos="0.0 0.266 -0.47" axisangle="1 0 0 0.05">
              <geom name="trg4" rgba="0.2 0.2 0.2 1" type="box" size="0.01 0.003 0.05" contype="1" conaffinity="1" />
          </body>
        </body>

        <body name="downrighthole" pos="0.1 -0.1 0">
          <body name="drg1" pos="0.034 0.3 -0.47" axisangle="0 1 0 0.05">
              <geom name="drg1" rgba="0.2 0.2 0.2 1" type="box" size="0.003 0.01 0.05" contype="1" conaffinity="1" />
          </body>

          <body name="drg2" pos="-0.034 0.3 -0.47" axisangle="0 1 0 -0.05">
              <geom name="drg2" rgba="0.2 0.2 0.2 1" type="box" size="0.003 0.01 0.05" contype="1" conaffinity="1" />
          </body>

          <body name="drg3" pos="0.0 0.334 -0.47" axisangle="1 0 0 -0.05">
              <geom name="drg3" rgba="0.2 0.2 0.2 1" type="box" size="0.01 0.003 0.05" contype="1" conaffinity="1" />
          </body>

          <body name="drg4" pos="0.0 0.266 -0.47" axisangle="1 0 0 0.05">
              <geom name="drg4" rgba="0.2 0.2 0.2 1" type="box" size="0.01 0.003 0.05" contype="1" conaffinity="1" />
          </body>
        </body>

        <body name="ground" pos="0.0 0.3 -0.55">
    		    <geom name="ground" rgba="0.2 0.2 0.2 1" type="box" size="0.4 0.4 0.05" contype="1" conaffinity="1" />
    		</body>

        <body name="crect1" pos="0.0 0.535 -0.45">
    		    <geom name="crect1" rgba="0 0 1 1" type="box" size="0.4 0.1 0.05" contype="1" conaffinity="1" />
    		</body>
        <body name="crect2" pos="0.0 0.3 -0.45">
    		    <geom name="crect2" rgba="0 0 1 1" type="box" size="0.4 0.066 0.05" contype="1" conaffinity="1" />
    		</body>
        <body name="crect3" pos="0.0 0.066 -0.45">
    		    <geom name="crect3" rgba="0 0 1 1" type="box" size="0.4 0.1 0.05" contype="1" conaffinity="1" />
    		</body>

        <body name="trect1" pos="-0.234 0.4 -0.45">
    		    <geom name="trect1" rgba="1 1 1 1" type="box" size="0.1 0.035 0.05" contype="1" conaffinity="1" />
    		</body>
        <body name="trect2" pos="0 0.4 -0.45">
    		    <geom name="trect2" rgba="0 1 0 1" type="box" size="0.066 0.035 0.05" contype="1" conaffinity="1" />
    		</body>
        <body name="trect3" pos="0.234 0.4 -0.45">
    		    <geom name="trect3" rgba="1 1 1 1" type="box" size="0.1 0.035 0.05" contype="1" conaffinity="1" />
    		</body>

        <body name="drect1" pos="-0.234 0.2 -0.45">
    		    <geom name="drect1" rgba="1 1 1 1" type="box" size="0.1 0.035 0.05" contype="1" conaffinity="1" />
    		</body>
        <body name="drect2" pos="0 0.2 -0.45">
    		    <geom name="drect2" rgba="0 1 0 1" type="box" size="0.066 0.035 0.05" contype="1" conaffinity="1" />
    		</body>
        <body name="drect3" pos="0.234 0.2 -0.45">
    		    <geom name="drect3" rgba="1 1 1 1" type="box" size="0.1 0.035 0.05" contype="1" conaffinity="1" />
    		</body>


    </worldbody>

    <actuator>
        <motor joint="r_shoulder_pan_joint" ctrlrange="-100.0 100.0" ctrllimited="true" />
        <motor joint="r_shoulder_lift_joint" ctrlrange="-100.0 100.0" ctrllimited="true" />
        <motor joint="r_upper_arm_roll_joint" ctrlrange="-100.0 100.0" ctrllimited="true" />
        <motor joint="r_elbow_flex_joint" ctrlrange="-100.0 100.0" ctrllimited="true" />
        <motor joint="r_forearm_roll_joint" ctrlrange="-100.0 100.0" ctrllimited="true" />
        <motor joint="r_wrist_flex_joint" ctrlrange="-100.0 100.0" ctrllimited="true" />
        <motor joint="r_wrist_roll_joint" ctrlrange="-100.0 100.0" ctrllimited="true" />
    </actuator>

</mujoco>
